2022-02-02 14:19:23,191:INFO:disnake.client: logging in using static token
2022-02-02 14:19:24,020:INFO:disnake.gateway: Shard ID None has sent the IDENTIFY payload.
2022-02-02 14:19:24,291:INFO:disnake.gateway: Shard ID None has connected to Gateway: ["gateway-prd-main-djzf",{"micros":191010,"calls":["discord-sessions-blue-prd-2-97",{"micros":189987,"calls":["start_session",{"micros":37137,"calls":["api-prd-main-6vxk",{"micros":33342,"calls":["get_user",{"micros":4207},"add_authorized_ip",{"micros":1478},"get_guilds",{"micros":8572},"coros_wait",{"micros":2}]}]},"guilds_connect",{"micros":14,"calls":[]},"presence_connect",{"micros":1,"calls":[]}]}]}] (Session ID: 0e9fe48e6050ef8645d5cf62a3d014af).
2022-02-02 14:20:33,917:WARNING:disnake.state: Shard ID 0 timed out waiting for chunks for guild_id 110373943822540800.
2022-02-02 14:22:04,096:WARNING:disnake.gateway: Shard ID None heartbeat blocked for more than 10 seconds.
Loop thread traceback (most recent call last):
  File "main.py", line 334, in <module>
    bot.run(bot_token)
  File "/opt/virtualenvs/python3/lib/python3.8/site-packages/disnake/client.py", line 833, in run
    loop.run_forever()
  File "/usr/lib/python3.8/asyncio/base_events.py", line 570, in run_forever
    self._run_once()
  File "/usr/lib/python3.8/asyncio/base_events.py", line 1859, in _run_once
    handle._run()
  File "/usr/lib/python3.8/asyncio/events.py", line 81, in _run
    self._context.run(self._callback, *self._args)
  File "/opt/virtualenvs/python3/lib/python3.8/site-packages/disnake/client.py", line 822, in runner
    await self.start(*args, **kwargs)
  File "/opt/virtualenvs/python3/lib/python3.8/site-packages/disnake/client.py", line 786, in start
    await self.connect(reconnect=reconnect)
  File "/opt/virtualenvs/python3/lib/python3.8/site-packages/disnake/client.py", line 683, in connect
    await self.ws.poll_event()
  File "/opt/virtualenvs/python3/lib/python3.8/site-packages/disnake/gateway.py", line 589, in poll_event
    await self.received_message(msg.data)
  File "/opt/virtualenvs/python3/lib/python3.8/site-packages/disnake/gateway.py", line 539, in received_message
    func(data)
  File "/opt/virtualenvs/python3/lib/python3.8/site-packages/disnake/state.py", line 1523, in parse_guild_members_chunk
    self.process_chunk_requests(guild_id, data.get("nonce"), members, complete)
  File "/opt/virtualenvs/python3/lib/python3.8/site-packages/disnake/state.py", line 314, in process_chunk_requests
    request.add_members(members)
  File "/opt/virtualenvs/python3/lib/python3.8/site-packages/disnake/state.py", line 133, in add_members
    existing = guild.get_member(member.id)
  File "/opt/virtualenvs/python3/lib/python3.8/site-packages/disnake/guild.py", line 837, in get_member
    return self._members.get(user_id)

2022-02-02 14:22:46,036:WARNING:disnake.gateway: Can't keep up, shard ID None websocket is 33.3s behind.
2022-02-02 14:23:05,038:WARNING:disnake.gateway: Shard ID None heartbeat blocked for more than 10 seconds.
Loop thread traceback (most recent call last):
  File "/opt/virtualenvs/python3/lib/python3.8/site-packages/aiohttp/client_ws.py", line 271, in receive
    return msg
  File "/opt/virtualenvs/python3/lib/python3.8/site-packages/async_timeout/__init__.py", line 39, in __enter__
    return self._do_enter()
  File "/opt/virtualenvs/python3/lib/python3.8/site-packages/async_timeout/__init__.py", line 86, in _do_enter
    return self
  File "/usr/lib/python3.8/asyncio/base_events.py", line 707, in call_at
    return timer
  File "/usr/lib/python3.8/asyncio/events.py", line 110, in __init__
    self._scheduled = False
  File "/usr/lib/python3.8/asyncio/events.py", line 45, in __init__
    self._source_traceback = None

2022-02-02 14:23:10,551:INFO:disnake.gateway: Websocket closed with 1006, attempting a reconnect.
2022-02-02 14:23:10,554:INFO:disnake.client: Got a request to RESUME the websocket.
2022-02-02 14:23:10,755:INFO:disnake.gateway: Shard ID None has sent the RESUME payload.
2022-02-02 14:23:10,974:INFO:disnake.gateway: Shard ID None session has been invalidated.
2022-02-02 14:23:11,059:INFO:disnake.client: Got a request to IDENTIFY the websocket.
2022-02-02 14:23:16,263:INFO:disnake.gateway: Shard ID None has sent the IDENTIFY payload.
2022-02-02 14:23:16,559:INFO:disnake.gateway: Shard ID None has connected to Gateway: ["gateway-prd-main-fwlz",{"micros":203340,"calls":["discord-sessions-blue-prd-2-56",{"micros":202485,"calls":["start_session",{"micros":32647,"calls":["api-prd-main-bdr0",{"micros":29184,"calls":["get_user",{"micros":2677},"add_authorized_ip",{"micros":2414},"get_guilds",{"micros":4586},"coros_wait",{"micros":1}]}]},"guilds_connect",{"micros":14,"calls":[]},"presence_connect",{"micros":2,"calls":[]}]}]}] (Session ID: 68bcfebded1dfe032702466b72c17764).
2022-02-02 14:24:02,699:WARNING:disnake.gateway: Shard ID None heartbeat blocked for more than 10 seconds.
Loop thread traceback (most recent call last):
  File "main.py", line 334, in <module>
    bot.run(bot_token)
  File "/opt/virtualenvs/python3/lib/python3.8/site-packages/disnake/client.py", line 833, in run
    loop.run_forever()
  File "/usr/lib/python3.8/asyncio/base_events.py", line 570, in run_forever
    self._run_once()
  File "/usr/lib/python3.8/asyncio/base_events.py", line 1859, in _run_once
    handle._run()
  File "/usr/lib/python3.8/asyncio/events.py", line 81, in _run
    self._context.run(self._callback, *self._args)
  File "/opt/virtualenvs/python3/lib/python3.8/site-packages/disnake/client.py", line 822, in runner
    await self.start(*args, **kwargs)
  File "/opt/virtualenvs/python3/lib/python3.8/site-packages/disnake/client.py", line 786, in start
    await self.connect(reconnect=reconnect)
  File "/opt/virtualenvs/python3/lib/python3.8/site-packages/disnake/client.py", line 683, in connect
    await self.ws.poll_event()
  File "/opt/virtualenvs/python3/lib/python3.8/site-packages/disnake/gateway.py", line 589, in poll_event
    await self.received_message(msg.data)
  File "/opt/virtualenvs/python3/lib/python3.8/site-packages/disnake/gateway.py", line 539, in received_message
    func(data)
  File "/opt/virtualenvs/python3/lib/python3.8/site-packages/disnake/state.py", line 1316, in parse_guild_create
    guild = self._get_create_guild(data)
  File "/opt/virtualenvs/python3/lib/python3.8/site-packages/disnake/state.py", line 1278, in _get_create_guild
    guild._from_data(data)
  File "/opt/virtualenvs/python3/lib/python3.8/site-packages/disnake/guild.py", line 536, in _from_data
    member = Member(data=mdata, guild=self, state=state)  # type: ignore
  File "/opt/virtualenvs/python3/lib/python3.8/site-packages/disnake/member.py", line 314, in __init__
    self._user: User = state.store_user(data["user"])
  File "/opt/virtualenvs/python3/lib/python3.8/site-packages/disnake/state.py", line 372, in store_user
    user = User(state=self, data=data)
  File "/opt/virtualenvs/python3/lib/python3.8/site-packages/disnake/user.py", line 440, in __init__
    super().__init__(state=state, data=data)
  File "/opt/virtualenvs/python3/lib/python3.8/site-packages/disnake/user.py", line 91, in __init__
    self._update(data)
  File "/opt/virtualenvs/python3/lib/python3.8/site-packages/disnake/user.py", line 120, in _update
    self.system = data.get("system", False)

2022-02-02 14:24:29,207:WARNING:disnake.gateway: Shard ID None heartbeat blocked for more than 20 seconds.
Loop thread traceback (most recent call last):
  File "main.py", line 334, in <module>
    bot.run(bot_token)
  File "/opt/virtualenvs/python3/lib/python3.8/site-packages/disnake/client.py", line 833, in run
    loop.run_forever()
  File "/usr/lib/python3.8/asyncio/base_events.py", line 570, in run_forever
    self._run_once()
  File "/usr/lib/python3.8/asyncio/base_events.py", line 1859, in _run_once
    handle._run()
  File "/usr/lib/python3.8/asyncio/events.py", line 81, in _run
    self._context.run(self._callback, *self._args)
  File "/opt/virtualenvs/python3/lib/python3.8/site-packages/disnake/client.py", line 822, in runner
    await self.start(*args, **kwargs)
  File "/opt/virtualenvs/python3/lib/python3.8/site-packages/disnake/client.py", line 786, in start
    await self.connect(reconnect=reconnect)
  File "/opt/virtualenvs/python3/lib/python3.8/site-packages/disnake/client.py", line 683, in connect
    await self.ws.poll_event()
  File "/opt/virtualenvs/python3/lib/python3.8/site-packages/disnake/gateway.py", line 589, in poll_event
    await self.received_message(msg.data)
  File "/opt/virtualenvs/python3/lib/python3.8/site-packages/disnake/gateway.py", line 539, in received_message
    func(data)
  File "/opt/virtualenvs/python3/lib/python3.8/site-packages/disnake/state.py", line 1316, in parse_guild_create
    guild = self._get_create_guild(data)
  File "/opt/virtualenvs/python3/lib/python3.8/site-packages/disnake/state.py", line 1278, in _get_create_guild
    guild._from_data(data)
  File "/opt/virtualenvs/python3/lib/python3.8/site-packages/disnake/guild.py", line 536, in _from_data
    member = Member(data=mdata, guild=self, state=state)  # type: ignore
  File "/opt/virtualenvs/python3/lib/python3.8/site-packages/disnake/member.py", line 327, in __init__
    self._communication_disabled_until: Optional[datetime.datetime] = timeout_datetime
  File "/opt/virtualenvs/python3/lib/python3.8/site-packages/disnake/state.py", line 376, in store_user
    return user

2022-02-02 14:24:34,337:INFO:disnake.gateway: Websocket closed with 1006, attempting a reconnect.
2022-02-02 14:24:35,618:INFO:disnake.client: Got a request to RESUME the websocket.
2022-02-02 14:24:36,400:INFO:disnake.gateway: Shard ID None has sent the RESUME payload.
2022-02-02 14:24:41,495:INFO:disnake.gateway: Shard ID None session has been invalidated.
2022-02-02 14:24:41,663:INFO:disnake.client: Got a request to IDENTIFY the websocket.
2022-02-02 14:24:47,074:INFO:disnake.gateway: Shard ID None has sent the IDENTIFY payload.
2022-02-02 14:24:47,483:INFO:disnake.gateway: Shard ID None has connected to Gateway: ["gateway-prd-main-4v95",{"micros":320103,"calls":["discord-sessions-blue-prd-2-132",{"micros":304672,"calls":["start_session",{"micros":61538,"calls":["api-prd-main-33r8",{"micros":56600,"calls":["get_user",{"micros":6058},"add_authorized_ip",{"micros":3291},"get_guilds",{"micros":8988},"coros_wait",{"micros":2}]}]},"guilds_connect",{"micros":9,"calls":[]},"presence_connect",{"micros":0,"calls":[]}]}]}] (Session ID: 8dd6199eaa9dc3417e9b90e24533ac71).
2022-02-02 14:25:55,489:WARNING:disnake.gateway: Shard ID None heartbeat blocked for more than 10 seconds.
Loop thread traceback (most recent call last):
  File "main.py", line 334, in <module>
    bot.run(bot_token)
  File "/opt/virtualenvs/python3/lib/python3.8/site-packages/disnake/client.py", line 833, in run
    loop.run_forever()
  File "/usr/lib/python3.8/asyncio/base_events.py", line 570, in run_forever
    self._run_once()
  File "/usr/lib/python3.8/asyncio/base_events.py", line 1859, in _run_once
    handle._run()
  File "/usr/lib/python3.8/asyncio/events.py", line 81, in _run
    self._context.run(self._callback, *self._args)
  File "/opt/virtualenvs/python3/lib/python3.8/site-packages/disnake/client.py", line 822, in runner
    await self.start(*args, **kwargs)
  File "/opt/virtualenvs/python3/lib/python3.8/site-packages/disnake/client.py", line 786, in start
    await self.connect(reconnect=reconnect)
  File "/opt/virtualenvs/python3/lib/python3.8/site-packages/disnake/client.py", line 683, in connect
    await self.ws.poll_event()
  File "/opt/virtualenvs/python3/lib/python3.8/site-packages/disnake/gateway.py", line 589, in poll_event
    await self.received_message(msg.data)
  File "/opt/virtualenvs/python3/lib/python3.8/site-packages/disnake/gateway.py", line 539, in received_message
    func(data)
  File "/opt/virtualenvs/python3/lib/python3.8/site-packages/disnake/state.py", line 1316, in parse_guild_create
    guild = self._get_create_guild(data)
  File "/opt/virtualenvs/python3/lib/python3.8/site-packages/disnake/state.py", line 1278, in _get_create_guild
    guild._from_data(data)
  File "/opt/virtualenvs/python3/lib/python3.8/site-packages/disnake/guild.py", line 536, in _from_data
    member = Member(data=mdata, guild=self, state=state)  # type: ignore
  File "/opt/virtualenvs/python3/lib/python3.8/site-packages/disnake/member.py", line 314, in __init__
    self._user: User = state.store_user(data["user"])
  File "/opt/virtualenvs/python3/lib/python3.8/site-packages/disnake/state.py", line 370, in store_user
    return self._users[user_id]

2022-02-02 14:26:10,549:WARNING:disnake.gateway: Shard ID None heartbeat blocked for more than 20 seconds.
Loop thread traceback (most recent call last):
  File "main.py", line 334, in <module>
    bot.run(bot_token)
  File "/opt/virtualenvs/python3/lib/python3.8/site-packages/disnake/client.py", line 833, in run
    loop.run_forever()
  File "/usr/lib/python3.8/asyncio/base_events.py", line 570, in run_forever
    self._run_once()
  File "/usr/lib/python3.8/asyncio/base_events.py", line 1859, in _run_once
    handle._run()
  File "/usr/lib/python3.8/asyncio/events.py", line 81, in _run
    self._context.run(self._callback, *self._args)
  File "/opt/virtualenvs/python3/lib/python3.8/site-packages/disnake/client.py", line 822, in runner
    await self.start(*args, **kwargs)
  File "/opt/virtualenvs/python3/lib/python3.8/site-packages/disnake/client.py", line 786, in start
    await self.connect(reconnect=reconnect)
  File "/opt/virtualenvs/python3/lib/python3.8/site-packages/disnake/client.py", line 683, in connect
    await self.ws.poll_event()
  File "/opt/virtualenvs/python3/lib/python3.8/site-packages/disnake/gateway.py", line 589, in poll_event
    await self.received_message(msg.data)
  File "/opt/virtualenvs/python3/lib/python3.8/site-packages/disnake/gateway.py", line 450, in received_message
    msg = utils._from_json(msg)
  File "/usr/lib/python3.8/json/__init__.py", line 357, in loads
    return _default_decoder.decode(s)
  File "/usr/lib/python3.8/json/decoder.py", line 337, in decode
    obj, end = self.raw_decode(s, idx=_w(s, 0).end())
  File "/usr/lib/python3.8/json/decoder.py", line 353, in raw_decode
    obj, end = self.scan_once(s, idx)

2022-02-02 14:26:15,705:INFO:disnake.gateway: Websocket closed with 1006, attempting a reconnect.
2022-02-02 14:26:15,705:INFO:disnake.client: Got a request to RESUME the websocket.
2022-02-02 14:26:16,489:INFO:disnake.gateway: Shard ID None has sent the RESUME payload.
2022-02-02 14:26:19,181:INFO:disnake.gateway: Shard ID None session has been invalidated.
2022-02-02 14:26:19,273:INFO:disnake.client: Got a request to IDENTIFY the websocket.
2022-02-02 14:26:24,481:INFO:disnake.gateway: Shard ID None has sent the IDENTIFY payload.
2022-02-02 14:26:24,728:INFO:disnake.gateway: Shard ID None has connected to Gateway: ["gateway-prd-main-ks32",{"micros":163891,"calls":["discord-sessions-blue-prd-2-128",{"micros":163031,"calls":["start_session",{"micros":47223,"calls":["api-prd-main-8554",{"micros":43632,"calls":["get_user",{"micros":11644},"add_authorized_ip",{"micros":1348},"get_guilds",{"micros":3189},"coros_wait",{"micros":1}]}]},"guilds_connect",{"micros":9,"calls":[]},"presence_connect",{"micros":3,"calls":[]}]}]}] (Session ID: e55926e0934ffb7adc93a1848b62d3ad).
2022-02-02 14:27:22,270:WARNING:disnake.gateway: Shard ID None heartbeat blocked for more than 10 seconds.
Loop thread traceback (most recent call last):
  File "main.py", line 334, in <module>
    bot.run(bot_token)
  File "/opt/virtualenvs/python3/lib/python3.8/site-packages/disnake/client.py", line 833, in run
    loop.run_forever()
  File "/usr/lib/python3.8/asyncio/base_events.py", line 570, in run_forever
    self._run_once()
  File "/usr/lib/python3.8/asyncio/base_events.py", line 1859, in _run_once
    handle._run()
  File "/usr/lib/python3.8/asyncio/events.py", line 81, in _run
    self._context.run(self._callback, *self._args)
  File "/opt/virtualenvs/python3/lib/python3.8/site-packages/disnake/client.py", line 822, in runner
    await self.start(*args, **kwargs)
  File "/opt/virtualenvs/python3/lib/python3.8/site-packages/disnake/client.py", line 786, in start
    await self.connect(reconnect=reconnect)
  File "/opt/virtualenvs/python3/lib/python3.8/site-packages/disnake/client.py", line 683, in connect
    await self.ws.poll_event()
  File "/opt/virtualenvs/python3/lib/python3.8/site-packages/disnake/gateway.py", line 589, in poll_event
    await self.received_message(msg.data)
  File "/opt/virtualenvs/python3/lib/python3.8/site-packages/disnake/gateway.py", line 450, in received_message
    msg = utils._from_json(msg)
  File "/usr/lib/python3.8/json/__init__.py", line 357, in loads
    return _default_decoder.decode(s)
  File "/usr/lib/python3.8/json/decoder.py", line 337, in decode
    obj, end = self.raw_decode(s, idx=_w(s, 0).end())
  File "/usr/lib/python3.8/json/decoder.py", line 353, in raw_decode
    obj, end = self.scan_once(s, idx)
  File "/opt/virtualenvs/python3/lib/python3.8/site-packages/disnake/user.py", line 449, in __del__
    self._state.deref_user(self.id)
  File "/opt/virtualenvs/python3/lib/python3.8/site-packages/disnake/state.py", line 379, in deref_user
    self._users.pop(user_id, None)

2022-02-02 14:27:55,137:WARNING:disnake.gateway: Shard ID None heartbeat blocked for more than 20 seconds.
Loop thread traceback (most recent call last):
  File "main.py", line 334, in <module>
    bot.run(bot_token)
  File "/opt/virtualenvs/python3/lib/python3.8/site-packages/disnake/client.py", line 833, in run
    loop.run_forever()
  File "/usr/lib/python3.8/asyncio/base_events.py", line 570, in run_forever
    self._run_once()
  File "/usr/lib/python3.8/asyncio/base_events.py", line 1859, in _run_once
    handle._run()
  File "/usr/lib/python3.8/asyncio/events.py", line 81, in _run
    self._context.run(self._callback, *self._args)
  File "/opt/virtualenvs/python3/lib/python3.8/site-packages/disnake/client.py", line 822, in runner
    await self.start(*args, **kwargs)
  File "/opt/virtualenvs/python3/lib/python3.8/site-packages/disnake/client.py", line 786, in start
    await self.connect(reconnect=reconnect)
  File "/opt/virtualenvs/python3/lib/python3.8/site-packages/disnake/client.py", line 683, in connect
    await self.ws.poll_event()
  File "/opt/virtualenvs/python3/lib/python3.8/site-packages/disnake/gateway.py", line 589, in poll_event
    await self.received_message(msg.data)
  File "/opt/virtualenvs/python3/lib/python3.8/site-packages/disnake/gateway.py", line 539, in received_message
    func(data)
  File "/opt/virtualenvs/python3/lib/python3.8/site-packages/disnake/state.py", line 1316, in parse_guild_create
    guild = self._get_create_guild(data)
  File "/opt/virtualenvs/python3/lib/python3.8/site-packages/disnake/state.py", line 1278, in _get_create_guild
    guild._from_data(data)
  File "/opt/virtualenvs/python3/lib/python3.8/site-packages/disnake/guild.py", line 536, in _from_data
    member = Member(data=mdata, guild=self, state=state)  # type: ignore
  File "/opt/virtualenvs/python3/lib/python3.8/site-packages/disnake/member.py", line 327, in __init__
    self._communication_disabled_until: Optional[datetime.datetime] = timeout_datetime
  File "/opt/virtualenvs/python3/lib/python3.8/site-packages/disnake/utils.py", line 656, in __new__
    return array.array.__new__(cls, "Q", data if is_sorted else sorted(data))  # type: ignore

2022-02-02 14:28:05,183:WARNING:disnake.gateway: Shard ID None heartbeat blocked for more than 30 seconds.
Loop thread traceback (most recent call last):
  File "main.py", line 334, in <module>
    bot.run(bot_token)
  File "/opt/virtualenvs/python3/lib/python3.8/site-packages/disnake/client.py", line 833, in run
    loop.run_forever()
  File "/usr/lib/python3.8/asyncio/base_events.py", line 570, in run_forever
    self._run_once()
  File "/usr/lib/python3.8/asyncio/base_events.py", line 1859, in _run_once
    handle._run()
  File "/usr/lib/python3.8/asyncio/events.py", line 81, in _run
    self._context.run(self._callback, *self._args)
  File "/opt/virtualenvs/python3/lib/python3.8/site-packages/disnake/client.py", line 822, in runner
    await self.start(*args, **kwargs)
  File "/opt/virtualenvs/python3/lib/python3.8/site-packages/disnake/client.py", line 786, in start
    await self.connect(reconnect=reconnect)
  File "/opt/virtualenvs/python3/lib/python3.8/site-packages/disnake/client.py", line 683, in connect
    await self.ws.poll_event()
  File "/opt/virtualenvs/python3/lib/python3.8/site-packages/disnake/gateway.py", line 589, in poll_event
    await self.received_message(msg.data)
  File "/opt/virtualenvs/python3/lib/python3.8/site-packages/disnake/gateway.py", line 539, in received_message
    func(data)
  File "/opt/virtualenvs/python3/lib/python3.8/site-packages/disnake/state.py", line 1316, in parse_guild_create
    guild = self._get_create_guild(data)
  File "/opt/virtualenvs/python3/lib/python3.8/site-packages/disnake/state.py", line 1278, in _get_create_guild
    guild._from_data(data)
  File "/opt/virtualenvs/python3/lib/python3.8/site-packages/disnake/guild.py", line 536, in _from_data
    member = Member(data=mdata, guild=self, state=state)  # type: ignore
  File "/opt/virtualenvs/python3/lib/python3.8/site-packages/disnake/member.py", line 314, in __init__
    self._user: User = state.store_user(data["user"])
  File "/opt/virtualenvs/python3/lib/python3.8/site-packages/disnake/state.py", line 370, in store_user
    return self._users[user_id]

2022-02-02 14:28:54,504:WARNING:disnake.gateway: Shard ID None heartbeat blocked for more than 40 seconds.
Loop thread traceback (most recent call last):
  File "main.py", line 334, in <module>
    bot.run(bot_token)
  File "/opt/virtualenvs/python3/lib/python3.8/site-packages/disnake/client.py", line 833, in run
    loop.run_forever()
  File "/usr/lib/python3.8/asyncio/base_events.py", line 570, in run_forever
    self._run_once()
  File "/usr/lib/python3.8/asyncio/base_events.py", line 1859, in _run_once
    handle._run()
  File "/usr/lib/python3.8/asyncio/events.py", line 81, in _run
    self._context.run(self._callback, *self._args)
  File "/opt/virtualenvs/python3/lib/python3.8/site-packages/disnake/client.py", line 822, in runner
    await self.start(*args, **kwargs)
  File "/opt/virtualenvs/python3/lib/python3.8/site-packages/disnake/client.py", line 786, in start
    await self.connect(reconnect=reconnect)
  File "/opt/virtualenvs/python3/lib/python3.8/site-packages/disnake/client.py", line 683, in connect
    await self.ws.poll_event()
  File "/opt/virtualenvs/python3/lib/python3.8/site-packages/disnake/gateway.py", line 589, in poll_event
    await self.received_message(msg.data)
  File "/opt/virtualenvs/python3/lib/python3.8/site-packages/disnake/gateway.py", line 539, in received_message
    func(data)
  File "/opt/virtualenvs/python3/lib/python3.8/site-packages/disnake/state.py", line 1316, in parse_guild_create
    guild = self._get_create_guild(data)
  File "/opt/virtualenvs/python3/lib/python3.8/site-packages/disnake/state.py", line 1278, in _get_create_guild
    guild._from_data(data)
  File "/opt/virtualenvs/python3/lib/python3.8/site-packages/disnake/guild.py", line 536, in _from_data
    member = Member(data=mdata, guild=self, state=state)  # type: ignore
  File "/opt/virtualenvs/python3/lib/python3.8/site-packages/disnake/member.py", line 314, in __init__
    self._user: User = state.store_user(data["user"])
  File "/opt/virtualenvs/python3/lib/python3.8/site-packages/disnake/state.py", line 370, in store_user
    return self._users[user_id]

2022-02-02 14:29:04,672:WARNING:disnake.gateway: Shard ID None heartbeat blocked for more than 50 seconds.
Loop thread traceback (most recent call last):
  File "main.py", line 334, in <module>
    bot.run(bot_token)
  File "/opt/virtualenvs/python3/lib/python3.8/site-packages/disnake/client.py", line 833, in run
    loop.run_forever()
  File "/usr/lib/python3.8/asyncio/base_events.py", line 570, in run_forever
    self._run_once()
  File "/usr/lib/python3.8/asyncio/base_events.py", line 1859, in _run_once
    handle._run()
  File "/usr/lib/python3.8/asyncio/events.py", line 81, in _run
    self._context.run(self._callback, *self._args)
  File "/opt/virtualenvs/python3/lib/python3.8/site-packages/disnake/client.py", line 822, in runner
    await self.start(*args, **kwargs)
  File "/opt/virtualenvs/python3/lib/python3.8/site-packages/disnake/client.py", line 786, in start
    await self.connect(reconnect=reconnect)
  File "/opt/virtualenvs/python3/lib/python3.8/site-packages/disnake/client.py", line 683, in connect
    await self.ws.poll_event()
  File "/opt/virtualenvs/python3/lib/python3.8/site-packages/disnake/gateway.py", line 589, in poll_event
    await self.received_message(msg.data)
  File "/opt/virtualenvs/python3/lib/python3.8/site-packages/disnake/gateway.py", line 539, in received_message
    func(data)
  File "/opt/virtualenvs/python3/lib/python3.8/site-packages/disnake/state.py", line 1316, in parse_guild_create
    guild = self._get_create_guild(data)
  File "/opt/virtualenvs/python3/lib/python3.8/site-packages/disnake/state.py", line 1278, in _get_create_guild
    guild._from_data(data)
  File "/opt/virtualenvs/python3/lib/python3.8/site-packages/disnake/guild.py", line 536, in _from_data
    member = Member(data=mdata, guild=self, state=state)  # type: ignore
  File "/opt/virtualenvs/python3/lib/python3.8/site-packages/disnake/member.py", line 314, in __init__
    self._user: User = state.store_user(data["user"])
  File "/opt/virtualenvs/python3/lib/python3.8/site-packages/disnake/state.py", line 372, in store_user
    user = User(state=self, data=data)
  File "/opt/virtualenvs/python3/lib/python3.8/site-packages/disnake/user.py", line 440, in __init__
    super().__init__(state=state, data=data)
  File "/opt/virtualenvs/python3/lib/python3.8/site-packages/disnake/user.py", line 91, in __init__
    self._update(data)
  File "/opt/virtualenvs/python3/lib/python3.8/site-packages/disnake/user.py", line 113, in _update
    self.id = int(data["id"])

2022-02-02 14:29:16,591:WARNING:disnake.gateway: Shard ID None heartbeat blocked for more than 60 seconds.
Loop thread traceback (most recent call last):
  File "main.py", line 334, in <module>
    bot.run(bot_token)
  File "/opt/virtualenvs/python3/lib/python3.8/site-packages/disnake/client.py", line 833, in run
    loop.run_forever()
  File "/usr/lib/python3.8/asyncio/base_events.py", line 570, in run_forever
    self._run_once()
  File "/usr/lib/python3.8/asyncio/base_events.py", line 1859, in _run_once
    handle._run()
  File "/usr/lib/python3.8/asyncio/events.py", line 81, in _run
    self._context.run(self._callback, *self._args)
  File "/opt/virtualenvs/python3/lib/python3.8/site-packages/disnake/client.py", line 822, in runner
    await self.start(*args, **kwargs)
  File "/opt/virtualenvs/python3/lib/python3.8/site-packages/disnake/client.py", line 786, in start
    await self.connect(reconnect=reconnect)
  File "/opt/virtualenvs/python3/lib/python3.8/site-packages/disnake/client.py", line 683, in connect
    await self.ws.poll_event()
  File "/opt/virtualenvs/python3/lib/python3.8/site-packages/disnake/gateway.py", line 589, in poll_event
    await self.received_message(msg.data)
  File "/opt/virtualenvs/python3/lib/python3.8/site-packages/disnake/gateway.py", line 539, in received_message
    func(data)
  File "/opt/virtualenvs/python3/lib/python3.8/site-packages/disnake/state.py", line 1316, in parse_guild_create
    guild = self._get_create_guild(data)
  File "/opt/virtualenvs/python3/lib/python3.8/site-packages/disnake/state.py", line 1278, in _get_create_guild
    guild._from_data(data)
  File "/opt/virtualenvs/python3/lib/python3.8/site-packages/disnake/guild.py", line 534, in _from_data
    for mdata in guild.get("members", []):

2022-02-02 14:29:26,720:WARNING:disnake.gateway: Shard ID None heartbeat blocked for more than 70 seconds.
Loop thread traceback (most recent call last):
  File "main.py", line 334, in <module>
    bot.run(bot_token)
  File "/opt/virtualenvs/python3/lib/python3.8/site-packages/disnake/client.py", line 833, in run
    loop.run_forever()
  File "/usr/lib/python3.8/asyncio/base_events.py", line 570, in run_forever
    self._run_once()
  File "/usr/lib/python3.8/asyncio/base_events.py", line 1859, in _run_once
    handle._run()
  File "/usr/lib/python3.8/asyncio/events.py", line 81, in _run
    self._context.run(self._callback, *self._args)
  File "/opt/virtualenvs/python3/lib/python3.8/site-packages/disnake/client.py", line 822, in runner
    await self.start(*args, **kwargs)
  File "/opt/virtualenvs/python3/lib/python3.8/site-packages/disnake/client.py", line 786, in start
    await self.connect(reconnect=reconnect)
  File "/opt/virtualenvs/python3/lib/python3.8/site-packages/disnake/client.py", line 683, in connect
    await self.ws.poll_event()
  File "/opt/virtualenvs/python3/lib/python3.8/site-packages/disnake/gateway.py", line 589, in poll_event
    await self.received_message(msg.data)
  File "/opt/virtualenvs/python3/lib/python3.8/site-packages/disnake/gateway.py", line 539, in received_message
    func(data)
  File "/opt/virtualenvs/python3/lib/python3.8/site-packages/disnake/state.py", line 1316, in parse_guild_create
    guild = self._get_create_guild(data)
  File "/opt/virtualenvs/python3/lib/python3.8/site-packages/disnake/state.py", line 1278, in _get_create_guild
    guild._from_data(data)
  File "/opt/virtualenvs/python3/lib/python3.8/site-packages/disnake/guild.py", line 536, in _from_data
    member = Member(data=mdata, guild=self, state=state)  # type: ignore
  File "/opt/virtualenvs/python3/lib/python3.8/site-packages/disnake/member.py", line 314, in __init__
    self._user: User = state.store_user(data["user"])
  File "/opt/virtualenvs/python3/lib/python3.8/site-packages/disnake/state.py", line 372, in store_user
    user = User(state=self, data=data)
  File "/opt/virtualenvs/python3/lib/python3.8/site-packages/disnake/user.py", line 437, in __init__
    def __init__(

2022-02-02 14:29:36,836:WARNING:disnake.gateway: Shard ID None heartbeat blocked for more than 80 seconds.
Loop thread traceback (most recent call last):
  File "main.py", line 334, in <module>
    bot.run(bot_token)
  File "/opt/virtualenvs/python3/lib/python3.8/site-packages/disnake/client.py", line 833, in run
    loop.run_forever()
  File "/usr/lib/python3.8/asyncio/base_events.py", line 570, in run_forever
    self._run_once()
  File "/usr/lib/python3.8/asyncio/base_events.py", line 1859, in _run_once
    handle._run()
  File "/usr/lib/python3.8/asyncio/events.py", line 81, in _run
    self._context.run(self._callback, *self._args)
  File "/opt/virtualenvs/python3/lib/python3.8/site-packages/disnake/client.py", line 822, in runner
    await self.start(*args, **kwargs)
  File "/opt/virtualenvs/python3/lib/python3.8/site-packages/disnake/client.py", line 786, in start
    await self.connect(reconnect=reconnect)
  File "/opt/virtualenvs/python3/lib/python3.8/site-packages/disnake/client.py", line 683, in connect
    await self.ws.poll_event()
  File "/opt/virtualenvs/python3/lib/python3.8/site-packages/disnake/gateway.py", line 589, in poll_event
    await self.received_message(msg.data)
  File "/opt/virtualenvs/python3/lib/python3.8/site-packages/disnake/gateway.py", line 539, in received_message
    func(data)
  File "/opt/virtualenvs/python3/lib/python3.8/site-packages/disnake/state.py", line 1316, in parse_guild_create
    guild = self._get_create_guild(data)
  File "/opt/virtualenvs/python3/lib/python3.8/site-packages/disnake/state.py", line 1278, in _get_create_guild
    guild._from_data(data)
  File "/opt/virtualenvs/python3/lib/python3.8/site-packages/disnake/guild.py", line 536, in _from_data
    member = Member(data=mdata, guild=self, state=state)  # type: ignore
  File "/opt/virtualenvs/python3/lib/python3.8/site-packages/disnake/member.py", line 320, in __init__
    self._roles: utils.SnowflakeList = utils.SnowflakeList(map(int, data["roles"]))
  File "/opt/virtualenvs/python3/lib/python3.8/site-packages/disnake/utils.py", line 656, in __new__
    return array.array.__new__(cls, "Q", data if is_sorted else sorted(data))  # type: ignore

2022-02-02 14:30:08,966:WARNING:disnake.gateway: Shard ID None heartbeat blocked for more than 90 seconds.
Loop thread traceback (most recent call last):
  File "main.py", line 334, in <module>
    bot.run(bot_token)
  File "/opt/virtualenvs/python3/lib/python3.8/site-packages/disnake/client.py", line 833, in run
    loop.run_forever()
  File "/usr/lib/python3.8/asyncio/base_events.py", line 570, in run_forever
    self._run_once()
  File "/usr/lib/python3.8/asyncio/base_events.py", line 1859, in _run_once
    handle._run()
  File "/usr/lib/python3.8/asyncio/events.py", line 81, in _run
    self._context.run(self._callback, *self._args)
  File "/opt/virtualenvs/python3/lib/python3.8/site-packages/disnake/client.py", line 822, in runner
    await self.start(*args, **kwargs)
  File "/opt/virtualenvs/python3/lib/python3.8/site-packages/disnake/client.py", line 786, in start
    await self.connect(reconnect=reconnect)
  File "/opt/virtualenvs/python3/lib/python3.8/site-packages/disnake/client.py", line 683, in connect
    await self.ws.poll_event()
  File "/opt/virtualenvs/python3/lib/python3.8/site-packages/disnake/gateway.py", line 589, in poll_event
    await self.received_message(msg.data)
  File "/opt/virtualenvs/python3/lib/python3.8/site-packages/disnake/gateway.py", line 539, in received_message
    func(data)
  File "/opt/virtualenvs/python3/lib/python3.8/site-packages/disnake/state.py", line 1316, in parse_guild_create
    guild = self._get_create_guild(data)
  File "/opt/virtualenvs/python3/lib/python3.8/site-packages/disnake/state.py", line 1278, in _get_create_guild
    guild._from_data(data)
  File "/opt/virtualenvs/python3/lib/python3.8/site-packages/disnake/guild.py", line 540, in _from_data
    self._sync(guild)
  File "/opt/virtualenvs/python3/lib/python3.8/site-packages/disnake/guild.py", line 561, in _sync
    member._presence_update(presence, empty_tuple)  # type: ignore
  File "/opt/virtualenvs/python3/lib/python3.8/site-packages/disnake/member.py", line 420, in _presence_update
    self.activities = tuple(map(create_activity, data["activities"]))
  File "/opt/virtualenvs/python3/lib/python3.8/site-packages/disnake/activity.py", line 873, in create_activity
    return Activity(**data)

2022-02-02 14:30:11,121:INFO:disnake.gateway: Websocket closed with 1006, attempting a reconnect.
2022-02-02 14:30:11,121:INFO:disnake.client: Got a request to RESUME the websocket.
2022-02-02 14:30:18,624:INFO:disnake.gateway: Shard ID None has sent the RESUME payload.
2022-02-02 14:30:18,707:INFO:disnake.gateway: Shard ID None session has been invalidated.
2022-02-02 14:30:18,793:INFO:disnake.client: Got a request to IDENTIFY the websocket.
2022-02-02 14:30:24,088:INFO:disnake.gateway: Shard ID None has sent the IDENTIFY payload.
2022-02-02 14:30:24,348:INFO:disnake.gateway: Shard ID None has connected to Gateway: ["gateway-prd-main-56hk",{"micros":179208,"calls":["discord-sessions-blue-prd-2-162",{"micros":177420,"calls":["start_session",{"micros":30561,"calls":["api-prd-main-b2h2",{"micros":27055,"calls":["get_user",{"micros":3115},"add_authorized_ip",{"micros":1377},"get_guilds",{"micros":3036},"coros_wait",{"micros":1}]}]},"guilds_connect",{"micros":12,"calls":[]},"presence_connect",{"micros":1,"calls":[]}]}]}] (Session ID: 940d1119feedc8c480c026c23a4205e0).
2022-02-02 14:31:21,028:WARNING:disnake.gateway: Shard ID None heartbeat blocked for more than 10 seconds.
Loop thread traceback (most recent call last):
  File "main.py", line 334, in <module>
    bot.run(bot_token)
  File "/opt/virtualenvs/python3/lib/python3.8/site-packages/disnake/client.py", line 833, in run
    loop.run_forever()
  File "/usr/lib/python3.8/asyncio/base_events.py", line 570, in run_forever
    self._run_once()
  File "/usr/lib/python3.8/asyncio/base_events.py", line 1859, in _run_once
    handle._run()
  File "/usr/lib/python3.8/asyncio/events.py", line 81, in _run
    self._context.run(self._callback, *self._args)
  File "/opt/virtualenvs/python3/lib/python3.8/site-packages/disnake/client.py", line 822, in runner
    await self.start(*args, **kwargs)
  File "/opt/virtualenvs/python3/lib/python3.8/site-packages/disnake/client.py", line 786, in start
    await self.connect(reconnect=reconnect)
  File "/opt/virtualenvs/python3/lib/python3.8/site-packages/disnake/client.py", line 683, in connect
    await self.ws.poll_event()
  File "/opt/virtualenvs/python3/lib/python3.8/site-packages/disnake/gateway.py", line 589, in poll_event
    await self.received_message(msg.data)
  File "/opt/virtualenvs/python3/lib/python3.8/site-packages/disnake/gateway.py", line 539, in received_message
    func(data)
  File "/opt/virtualenvs/python3/lib/python3.8/site-packages/disnake/state.py", line 1316, in parse_guild_create
    guild = self._get_create_guild(data)
  File "/opt/virtualenvs/python3/lib/python3.8/site-packages/disnake/state.py", line 1278, in _get_create_guild
    guild._from_data(data)
  File "/opt/virtualenvs/python3/lib/python3.8/site-packages/disnake/guild.py", line 536, in _from_data
    member = Member(data=mdata, guild=self, state=state)  # type: ignore
  File "/opt/virtualenvs/python3/lib/python3.8/site-packages/disnake/member.py", line 314, in __init__
    self._user: User = state.store_user(data["user"])
  File "/opt/virtualenvs/python3/lib/python3.8/site-packages/disnake/state.py", line 372, in store_user
    user = User(state=self, data=data)
  File "/opt/virtualenvs/python3/lib/python3.8/site-packages/disnake/user.py", line 440, in __init__
    super().__init__(state=state, data=data)

2022-02-02 14:31:33,024:WARNING:disnake.gateway: Shard ID None heartbeat blocked for more than 20 seconds.
Loop thread traceback (most recent call last):
  File "main.py", line 334, in <module>
    bot.run(bot_token)
  File "/opt/virtualenvs/python3/lib/python3.8/site-packages/disnake/client.py", line 833, in run
    loop.run_forever()
  File "/usr/lib/python3.8/asyncio/base_events.py", line 570, in run_forever
    self._run_once()
  File "/usr/lib/python3.8/asyncio/base_events.py", line 1859, in _run_once
    handle._run()
  File "/usr/lib/python3.8/asyncio/events.py", line 81, in _run
    self._context.run(self._callback, *self._args)
  File "/opt/virtualenvs/python3/lib/python3.8/site-packages/disnake/client.py", line 822, in runner
    await self.start(*args, **kwargs)
  File "/opt/virtualenvs/python3/lib/python3.8/site-packages/disnake/client.py", line 786, in start
    await self.connect(reconnect=reconnect)
  File "/opt/virtualenvs/python3/lib/python3.8/site-packages/disnake/client.py", line 683, in connect
    await self.ws.poll_event()
  File "/opt/virtualenvs/python3/lib/python3.8/site-packages/disnake/gateway.py", line 589, in poll_event
    await self.received_message(msg.data)
  File "/opt/virtualenvs/python3/lib/python3.8/site-packages/disnake/gateway.py", line 539, in received_message
    func(data)
  File "/opt/virtualenvs/python3/lib/python3.8/site-packages/disnake/state.py", line 1316, in parse_guild_create
    guild = self._get_create_guild(data)
  File "/opt/virtualenvs/python3/lib/python3.8/site-packages/disnake/state.py", line 1278, in _get_create_guild
    guild._from_data(data)
  File "/opt/virtualenvs/python3/lib/python3.8/site-packages/disnake/guild.py", line 536, in _from_data
    member = Member(data=mdata, guild=self, state=state)  # type: ignore
  File "/opt/virtualenvs/python3/lib/python3.8/site-packages/disnake/member.py", line 314, in __init__
    self._user: User = state.store_user(data["user"])
  File "/opt/virtualenvs/python3/lib/python3.8/site-packages/disnake/state.py", line 372, in store_user
    user = User(state=self, data=data)
  File "/opt/virtualenvs/python3/lib/python3.8/site-packages/disnake/user.py", line 440, in __init__
    super().__init__(state=state, data=data)
  File "/opt/virtualenvs/python3/lib/python3.8/site-packages/disnake/user.py", line 91, in __init__
    self._update(data)
  File "/opt/virtualenvs/python3/lib/python3.8/site-packages/disnake/user.py", line 118, in _update
    self._public_flags = data.get("public_flags", 0)

2022-02-02 14:31:36,960:INFO:disnake.gateway: Websocket closed with 1006, attempting a reconnect.
2022-02-02 14:31:37,154:INFO:disnake.client: Got a request to RESUME the websocket.
2022-02-02 14:31:37,357:INFO:disnake.gateway: Shard ID None has sent the RESUME payload.
2022-02-02 14:31:40,710:INFO:disnake.gateway: Shard ID None session has been invalidated.
2022-02-02 14:31:40,795:INFO:disnake.client: Got a request to IDENTIFY the websocket.
2022-02-02 14:31:44,190:WARNING:disnake.state: Shard ID 0 timed out waiting for chunks for guild_id 836680843660492820.
2022-02-02 14:31:45,985:INFO:disnake.gateway: Shard ID None has sent the IDENTIFY payload.
2022-02-02 14:31:46,223:INFO:disnake.gateway: Shard ID None has connected to Gateway: ["gateway-prd-main-fdh3",{"micros":156948,"calls":["discord-sessions-blue-prd-2-3",{"micros":156191,"calls":["start_session",{"micros":27346,"calls":["api-prd-main-kcrk",{"micros":23596,"calls":["get_user",{"micros":2666},"add_authorized_ip",{"micros":1221},"get_guilds",{"micros":4107},"coros_wait",{"micros":0}]}]},"guilds_connect",{"micros":10,"calls":[]},"presence_connect",{"micros":1,"calls":[]}]}]}] (Session ID: 501033dc2fe746516b186b0eaca3d3ca).
2022-02-02 14:31:54,604:WARNING:disnake.state: Shard ID 0 timed out waiting for chunks for guild_id 895004411863130153.
